Workbook

Sheet Mayor Mapping
A3: Count of CUTAM | B3: Column Labels
A4: Row Labels | B4: DA | C4: Ind. | D4: PAS | E4: PDCM | F4: PDMM | G4: PLDM | H4: PSDE | I4: PSRM | J4: Respect | K4: Grand Total
A5: 2026-01 | C5: 1 | D5: 2 | K5: 3
A6: 2026-02 | C6: 1 | D6: 2 | E6: 2 | H6: 1 | K6: 6
A7: 2026-03 | C7: 1 | F7: 2 | K7: 3
A8: 2026-04 | D8: 1 | I8: 2 | K8: 3
A9: 2026-05 | E9: 1 | H9: 1 | I9: 1 | J9: 2 | K9: 5
A10: 2026-06 | D10: 2 | K10: 2
A11: 2026-07 | C11: 1 | D11: 1 | K11: 2
A12: 2026-08 | C12: 1 | D12: 2 | J12: 1 | K12: 4
A13: 2026-09 | D13: 1 | G13: 1 | K13: 2
A14: 2026-10 | C14: 1 | D14: 2 | I14: 1 | K14: 4
A15: 2026-11 | D15: 2 | K15: 2
A16: 2026-12 | D16: 2 | I16: 2 | K16: 4
A17: 2026-13 | B17: 1 | D17: 3 | I17: 1 | K17: 5
A18: 2026-14 | D18: 1 | H18: 1 | K18: 2
A19: 2026-15 | D19: 2 | K19: 2
A20: 2026-16 | D20: 1 | I20: 2 | K20: 3
A21: Grand Total | B21: 1 | C21: 6 | D21: 24 | E21: 3 | F21: 2 | G21: 1 | H21: 3 | I21: 9 | J21: 3 | K21: 52

Sheet Council Mapping
A3: Count of CUTAM | B3: Column Labels
A4: Row Labels | B4: DA | C4: PAS | D4: PAS/PDCM | E4: PAS/PSDE | F4: PAS/PSRM | G4: PDCM | H4: PDCM/PAS | I4: PDCM/PSDE | J4: PDMM | K4: PLDM | L4: PLDM/DA | M4: PSDE | N4: PSDE/PAS | O4: PSDE/PAS/PSRM | P4: PSRM | Q4: PSRM/PAS | R4: Renaștere | S4: Respect | T4: Respect/PAS/PDCM | U4: Respect/PSRM | V4: Grand Total
A5: 2026-01 | C5: 2 | Q5: 1 | V5: 3
A6: 2026-02 | C6: 2 | E6: 1 | G6: 1 | I6: 1 | M6: 1 | V6: 6
A7: 2026-03 | J7: 2 | L7: 1 | V7: 3
A8: 2026-04 | C8: 1 | P8: 2 | V8: 3
A9: 2026-05 | H9: 1 | N9: 1 | P9: 1 | T9: 1 | U9: 1 | V9: 5
A10: 2026-06 | C10: 2 | V10: 2
A11: 2026-07 | C11: 1 | R11: 1 | V11: 2
A12: 2026-08 | D12: 1 | F12: 1 | Q12: 1 | S12: 1 | V12: 4
A13: 2026-09 | C13: 1 | K13: 1 | V13: 2
A14: 2026-10 | C14: 1 | O14: 1 | P14: 2 | V14: 4
A15: 2026-11 | C15: 2 | V15: 2
A16: 2026-12 | C16: 2 | P16: 1 | Q16: 1 | V16: 4
A17: 2026-13 | B17: 1 | C17: 1 | F17: 1 | P17: 1 | Q17: 1 | V17: 5
A18: 2026-14 | C18: 1 | M18: 1 | V18: 2
A19: 2026-15 | C19: 1 | N19: 1 | V19: 2
A20: 2026-16 | F20: 1 | P20: 2 | V20: 3
A21: Grand Total | B21: 1 | C21: 17 | D21: 1 | E21: 1 | F21: 3 | G21: 1 | H21: 1 | I21: 1 | J21: 2 | K21: 1 | L21: 1 | M21: 2 | N21: 2 | O21: 1 | P21: 9 | Q21: 4 | R21: 1 | S21: 1 | T21: 1 | U21: 1 | V21: 52

Sheet Individual
A1: Cluster_ID | B1: CUTAM | C1: Date | D1: Name | E1: Raion | F1: Mayor_Party | G1: Council_Party | H1: Upfront_grant (MDL M) | I1: Population (2024) | J1: km2 | K1: Below 1500 | L1: Below 3000 | M1: Source
A2: 2026-01 | B2: 1038 | C2: 46186 | D2: Roșcani | E2: Anenii Noi | F2: PAS | G2: PAS | H2: 15.3 | I2: =VLOOKUP(B2,Populations!$C$1:$F$900,4,FALSE) -> 1670 | J2: =VLOOKUP(B2,Area!$E$2:$F$896,2,FALSE) -> 16.3 | K2: =IF(I2<1500,1,0) -> 0 | L2: =IF(I2<3000,1,0) -> 1 | M2: https://radiomoldova.md/p/78588/trei-localitati-din-raionul-anenii-noi-au-decis-amalgamarea-voluntara
A3: 2026-01 | B3: 1043 | C3: 46186 | D3: Telița | E3: Anenii Noi | F3: PAS | G3: PAS | H3: 15.3 | I3: =VLOOKUP(B3,Populations!$C$1:$F$900,4,FALSE) -> 823 | J3: =VLOOKUP(B3,Area!$E$2:$F$896,2,FALSE) -> 21.489 | K3: =IF(I3<1500,1,0) -> 1 | L3: =IF(I3<3000,1,0) -> 1 | M3: https://radiomoldova.md/p/78588/trei-localitati-din-raionul-anenii-noi-au-decis-amalgamarea-voluntara
A4: 2026-01 | B4: 1015 | C4: 46186 | D4: Calfa | E4: Anenii Noi | F4: Ind. | G4: PSRM/PAS | H4: 15.3 | I4: =VLOOKUP(B4,Populations!$C$1:$F$900,4,FALSE) -> 1226 | J4: =VLOOKUP(B4,Area!$E$2:$F$896,2,FALSE) -> 21.537 | K4: =IF(I4<1500,1,0) -> 1 | L4: =IF(I4<3000,1,0) -> 1 | M4: https://radiomoldova.md/p/78588/trei-localitati-din-raionul-anenii-noi-au-decis-amalgamarea-voluntara
A5: 2026-02 | B5: 5310 | C5: 46196 | D5: Bălceana | E5: Hîncești | F5: Ind. | G5: PAS/PSDE | H5: 41 | I5: =VLOOKUP(B5,Populations!$C$1:$F$900,4,FALSE) -> 955 | J5: =VLOOKUP(B5,Area!$E$2:$F$896,2,FALSE) -> 29.838 | K5: =IF(I5<1500,1,0) -> 1 | L5: =IF(I5<3000,1,0) -> 1 | M5: https://democracy.md/sase-localitati-din-hancesti-se-unesc-intr-o-primarie-mai-mare-investitii-de-41-milioane-de-lei/
A6: 2026-02 | B6: 5314 | C6: 46196 | D6: Boghiceni | E6: Hîncești | F6: PAS | G6: PAS | H6: 41 | I6: =VLOOKUP(B6,Populations!$C$1:$F$900,4,FALSE) -> 1530 | J6: =VLOOKUP(B6,Area!$E$2:$F$896,2,FALSE) -> 39.092 | K6: =IF(I6<1500,1,0) -> 0 | L6: =IF(I6<3000,1,0) -> 1 | M6: https://democracy.md/sase-localitati-din-hancesti-se-unesc-intr-o-primarie-mai-mare-investitii-de-41-milioane-de-lei/
A7: 2026-02 | B7: 5337 | C7: 46196 | D7: Lăpușna | E7: Hîncești | F7: PAS | G7: PAS | H7: 41 | I7: =VLOOKUP(B7,Populations!$C$1:$F$900,4,FALSE) -> 3386 | J7: =VLOOKUP(B7,Area!$E$2:$F$896,2,FALSE) -> 89.077 | K7: =IF(I7<1500,1,0) -> 0 | L7: =IF(I7<3000,1,0) -> 0 | M7: https://democracy.md/sase-localitati-din-hancesti-se-unesc-intr-o-primarie-mai-mare-investitii-de-41-milioane-de-lei/
A8: 2026-02 | B8: 5354 | C8: 46196 | D8: Pașcani | E8: Hîncești | F8: PDCM | G8: PDCM | H8: 41 | I8: =VLOOKUP(B8,Populations!$C$1:$F$900,4,FALSE) -> 1424 | J8: =VLOOKUP(B8,Area!$E$2:$F$896,2,FALSE) -> 27.693 | K8: =IF(I8<1500,1,0) -> 1 | L8: =IF(I8<3000,1,0) -> 1 | M8: https://democracy.md/sase-localitati-din-hancesti-se-unesc-intr-o-primarie-mai-mare-investitii-de-41-milioane-de-lei/
A9: 2026-02 | B9: 5356 | C9: 46196 | D9: Pervomaiscoe | E9: Hîncești | F9: PDCM | G9: PDCM/PSDE | H9: 41 | I9: =VLOOKUP(B9,Populations!$C$1:$F$900,4,FALSE) -> 424 | J9: =VLOOKUP(B9,Area!$E$2:$F$896,2,FALSE) -> 15.191 | K9: =IF(I9<1500,1,0) -> 1 | L9: =IF(I9<3000,1,0) -> 1 | M9: https://democracy.md/sase-localitati-din-hancesti-se-unesc-intr-o-primarie-mai-mare-investitii-de-41-milioane-de-lei/
A10: 2026-02 | B10: 5361 | C10: 46196 | D10: Secăreni | E10: Hîncești | F10: PSDE | G10: PSDE | H10: 41 | I10: =VLOOKUP(B10,Populations!$C$1:$F$900,4,FALSE) -> 960 | J10: =VLOOKUP(B10,Area!$E$2:$F$896,2,FALSE) -> 22.053 | K10: =IF(I10<1500,1,0) -> 1 | L10: =IF(I10<3000,1,0) -> 1 | M10: https://democracy.md/sase-localitati-din-hancesti-se-unesc-intr-o-primarie-mai-mare-investitii-de-41-milioane-de-lei/
A11: 2026-03 | B11: 1742 | C11: 46207 | D11: Zîrnești | E11: Cahul | F11: PDMM | G11: PDMM | H11: 16 | I11: =VLOOKUP(B11,Populations!$C$1:$F$900,4,FALSE) -> 1544 | J11: =VLOOKUP(B11,Area!$E$2:$F$896,2,FALSE) -> 35.608 | K11: =IF(I11<1500,1,0) -> 0 | L11: =IF(I11<3000,1,0) -> 1 | M11: https://radiochisinau.md/amalgamare-voluntara-la-cahul-trei-localitati-se-unesc-intro-singura-primarie-cu-un-stimulent-de-16-milioane-de-lei-din-partea-guvernului---226237.html
A12: 2026-03 | B12: 1713 | C12: 46207 | D12: Baurci-Moldoveni | E12: Cahul | F12: PDMM | G12: PDMM | H12: 16 | I12: =VLOOKUP(B12,Populations!$C$1:$F$900,4,FALSE) -> 1285 | J12: =VLOOKUP(B12,Area!$E$2:$F$896,2,FALSE) -> 39.922 | K12: =IF(I12<1500,1,0) -> 1 | L12: =IF(I12<3000,1,0) -> 1 | M12: https://radiochisinau.md/amalgamare-voluntara-la-cahul-trei-localitati-se-unesc-intro-singura-primarie-cu-un-stimulent-de-16-milioane-de-lei-din-partea-guvernului---226237.html
A13: 2026-03 | B13: 1721 | C13: 46207 | D13: Cucoara | E13: Cahul | F13: Ind. | G13: PLDM/DA | H13: 16 | I13: =VLOOKUP(B13,Populations!$C$1:$F$900,4,FALSE) -> 1086 | J13: =VLOOKUP(B13,Area!$E$2:$F$896,2,FALSE) -> 34.893 | K13: =IF(I13<1500,1,0) -> 1 | L13: =IF(I13<3000,1,0) -> 1 | M13: https://radiochisinau.md/amalgamare-voluntara-la-cahul-trei-localitati-se-unesc-intro-singura-primarie-cu-un-stimulent-de-16-milioane-de-lei-din-partea-guvernului---226237.html
... A53: 2026-16 | B53: 7861 | C53: 46223 | D53: Vădeni | E53: Soroca | F53: PSRM | G53: PSRM | H53: 17 | I53: =VLOOKUP(B53,Populations!$C$1:$F$900,4,FALSE) -> 1194 | J53: =VLOOKUP(B53,Area!$E$2:$F$896,2,FALSE) -> 44.328 | K53: =IF(I53<1500,1,0) -> 1 | L53: =IF(I53<3000,1,0) -> 1 | M53: https://www.facebook.com/share/r/1EMYQxZcAn/

Sheet JSON
A1: Cluster_ID | B1: Cluster_Name | C1: Region_Raion | D1: Designated_Center | E1: Combined_Population | F1: Financial_Stimulus_MDL | G1: km2 | H1: Below_1500 | I1: Below_3000 | J1: Participating_Communities | K1: Mayor_Party | L1: Major_Council_Party | M1: Source
A2: 2026-01 | B2: Anenii Noi-02 | C2: Anenii Noi | D2: Roșcani | E2: =SUMIF(Individual!A:A,JSON!A2,Individual!I:I) -> 3719 | F2: =AVERAGEIF(Individual!A:A,JSON!A2,Individual!H:H) -> 15.3 | G2: =SUMIF(Individual!A:A,JSON!A2,Individual!J:J) -> 59.326 | H2: =SUMIF(Individual!A:A,JSON!A2,Individual!K:K) -> 2 | I2: =SUMIF(Individual!A:A,JSON!A2,Individual!L:L) -> 3 | J2: Roșcani; Telița; Calfa | K2: PAS;Ind. | L2: PAS;PSRM | M2: https://radiomoldova.md/p/78588/trei-localitati-din-raionul-anenii-noi-au-decis-amalgamarea-voluntara
A3: 2026-02 | B3: Hîncești-05 | C3: Hîncești | D3: Lăpușna | E3: =SUMIF(Individual!A:A,JSON!A3,Individual!I:I) -> 8679 | F3: =AVERAGEIF(Individual!A:A,JSON!A3,Individual!H:H) -> 41 | G3: =SUMIF(Individual!A:A,JSON!A3,Individual!J:J) -> 222.944 | H3: =SUMIF(Individual!A:A,JSON!A3,Individual!K:K) -> 4 | I3: =SUMIF(Individual!A:A,JSON!A3,Individual!L:L) -> 5 | J3: Bălceana; Boghiceni; Lăpușna; Pașcani; Pervomaiscoe; Secăreni | K3: PAS; Ind.;PSDE;PDCM | L3: PAS;PSDE;PDCM | M3: https://democracy.md/sase-localitati-din-hancesti-se-unesc-intr-o-primarie-mai-mare-investitii-de-41-milioane-de-lei/
A4: 2026-03 | B4: Cahul-06 | C4: Cahul | D4: Zîrnești | E4: =SUMIF(Individual!A:A,JSON!A4,Individual!I:I) -> 3915 | F4: =AVERAGEIF(Individual!A:A,JSON!A4,Individual!H:H) -> 16 | G4: =SUMIF(Individual!A:A,JSON!A4,Individual!J:J) -> 110.423 | H4: =SUMIF(Individual!A:A,JSON!A4,Individual!K:K) -> 2 | I4: =SUMIF(Individual!A:A,JSON!A4,Individual!L:L) -> 3 | J4: Zîrnești; Baurci-Moldoveni; Cucoara | K4: PDMM;Ind. | L4: PDMM;PLDM;DA | M4: https://radiochisinau.md/amalgamare-voluntara-la-cahul-trei-localitati-se-unesc-intro-singura-primarie-cu-un-stimulent-de-16-milioane-de-lei-din-partea-guvernului---226237.html
A5: 2026-04 | B5: Anenii Noi-04 | C5: Anenii Noi | D5: Geamăna | E5: =SUMIF(Individual!A:A,JSON!A5,Individual!I:I) -> 3234 | F5: =AVERAGEIF(Individual!A:A,JSON!A5,Individual!H:H) -> 13 | G5: =SUMIF(Individual!A:A,JSON!A5,Individual!J:J) -> 111.693 | H5: =SUMIF(Individual!A:A,JSON!A5,Individual!K:K) -> 2 | I5: =SUMIF(Individual!A:A,JSON!A5,Individual!L:L) -> 3 | J5: Geamăna; Zolotievca; Ochiul Roș | K5: PAS;PSRM | L5: PAS;PSRM | M5: https://radiochisinau.md/inca-trei-localitati-din-anenii-noi-se-amalgameaza-voluntar-guvernul-va-investi-13-milioane-de-lei---225535.html
A6: 2026-05 | B6: Florești/Șoldănești-01 | C6: Florești/Șoldănești | E6: =SUMIF(Individual!A:A,JSON!A6,Individual!I:I) -> 5592 | F6: =AVERAGEIF(Individual!A:A,JSON!A6,Individual!H:H) -> 25.9 | G6: =SUMIF(Individual!A:A,JSON!A6,Individual!J:J) -> 102.273 | H6: =SUMIF(Individual!A:A,JSON!A6,Individual!K:K) -> 4 | I6: =SUMIF(Individual!A:A,JSON!A6,Individual!L:L) -> 5 | J6: Orașul Ghindești; Domulgeni; Rogojeni; Roșietici; Ghindești | K6: Respect;PDCM;PSDE;PSRM | L6: Respect;PDCM;PSDE;PSRM | M6: https://radiochisinau.md/cinci-localitati-din-floresti-si-soldanesti-au-decis-sa-se-uneasca-intro-singura-primarie-circa-26-de-milioane-de-lei-oferite-de-guvern-pentru-dezvoltare---226071.html
A7: 2026-06 | B7: Ialoveni-05 | C7: Ialoveni | D7: Ialoveni | E7: =SUMIF(Individual!A:A,JSON!A7,Individual!I:I) -> 16103 | F7: =AVERAGEIF(Individual!A:A,JSON!A7,Individual!H:H) -> 54.6 | G7: =SUMIF(Individual!A:A,JSON!A7,Individual!J:J) -> 40.563 | H7: =SUMIF(Individual!A:A,JSON!A7,Individual!K:K) -> 1 | I7: =SUMIF(Individual!A:A,JSON!A7,Individual!L:L) -> 1 | J7: Orașul Ialoveni; Sociteni | K7: PAS | L7: PAS | M7: https://www.facebook.com/photo/?fbid=1010403035289948&set=pb.100089607821243.-2207520000
A8: 2026-07 | B8: Drochia-06 | C8: Drochia | D8: Sofia | E8: =SUMIF(Individual!A:A,JSON!A8,Individual!I:I) -> 3686 | F8: =AVERAGEIF(Individual!A:A,JSON!A8,Individual!H:H) -> 14.8 | G8: =SUMIF(Individual!A:A,JSON!A8,Individual!J:J) -> 78.556 | H8: =SUMIF(Individual!A:A,JSON!A8,Individual!K:K) -> 1 | I8: =SUMIF(Individual!A:A,JSON!A8,Individual!L:L) -> 2 | J8: Sofia; Miciurin | K8: PAS; Ind. | L8: PAS;Renaștere | M8: https://actelocale.gov.md/ral/act/cu-privire-la-amalgamarea-voluntară-a-unităților-administrativ-teritoriale-sofia-miciurin-2291823.html
A9: 2026-08 | B9: Florești-03 | C9: Florești | D9: Gura Camencii | E9: =SUMIF(Individual!A:A,JSON!A9,Individual!I:I) -> 4372 | F9: =AVERAGEIF(Individual!A:A,JSON!A9,Individual!H:H) -> 18.5 | G9: =SUMIF(Individual!A:A,JSON!A9,Individual!J:J) -> 117.415 | H9: =SUMIF(Individual!A:A,JSON!A9,Individual!K:K) -> 3 | I9: =SUMIF(Individual!A:A,JSON!A9,Individual!L:L) -> 4 | J9: Cernița; Ciripcău; Coșernița; Gura Camencii | K9: PAS;Ind. | L9: PAS;PSRM;PDCM | M9: https://www.facebook.com/AlexeiBuzuGov/posts/pfbid02wEwg3kfaekDgBR8p9q8vPi7v999iajdB4zEKmbwQshxnoE6AQD9EzdRLoh8pb4gQl
A10: 2026-09 | B10: Basarabeasca-01 | C10: Basarabeasca | D10: Abaclia | E10: =SUMIF(Individual!A:A,JSON!A10,Individual!I:I) -> 3290 | F10: =AVERAGEIF(Individual!A:A,JSON!A10,Individual!H:H) -> 13.2 | G10: =SUMIF(Individual!A:A,JSON!A10,Individual!J:J) -> 88.055 | H10: =SUMIF(Individual!A:A,JSON!A10,Individual!K:K) -> 1 | I10: =SUMIF(Individual!A:A,JSON!A10,Individual!L:L) -> 2 | J10: Abaclia; Iordanovca | K10: PLDM;PAS | L10: PLDM;PAS | M10: https://www.facebook.com/AlexeiBuzuGov/posts/pfbid02TZLVVNC7boN2XvUjx6R9hXS2nTo3ue6e6JW92zN2ABe4KFNSwLxhvTv797uQT59xl
A11: 2026-10 | B11: Soroca-01 | C11: Soroca | D11: Rublenița | E11: =SUMIF(Individual!A:A,JSON!A11,Individual!I:I) -> 4513 | F11: =AVERAGEIF(Individual!A:A,JSON!A11,Individual!H:H) -> 19.3 | G11: =SUMIF(Individual!A:A,JSON!A11,Individual!J:J) -> 91.861 | H11: =SUMIF(Individual!A:A,JSON!A11,Individual!K:K) -> 3 | I11: =SUMIF(Individual!A:A,JSON!A11,Individual!L:L) -> 4 | J11: Rublenița; Băxani; Șolcani; Șeptelici | K11: PAS;Ind.;PSRM | L11: PSDE;PAS;PSRM | M11: https://unika.md/news/patru-localitati-din-soroca-se-unesc-intr-o-singura-primarie-vor-primi-aproape-20-de-milioane
A12: 2026-11 | B12: Basarabeasca-02 | C12: Basarabeasca | D12: Sadaclia | E12: =SUMIF(Individual!A:A,JSON!A12,Individual!I:I) -> 3394 | F12: =AVERAGEIF(Individual!A:A,JSON!A12,Individual!H:H) -> 13.6 | G12: =SUMIF(Individual!A:A,JSON!A12,Individual!J:J) -> 74.16 | H12: =SUMIF(Individual!A:A,JSON!A12,Individual!K:K) -> 1 | I12: =SUMIF(Individual!A:A,JSON!A12,Individual!L:L) -> 2 | J12: Sadaclia; Carabetovca | K12: PAS | L12: PAS | M12: https://www.moldpres.md/rom/politica/grupuri-de-primarii-amalgamate-au-fost-create-in-toate-regiunile-tarii-investitii-de-366-de-milioane-de-lei-planificate-de-guvern-pentru-modernizarea-localitatilor
A13: 2026-12 | B13: Leova-05 | C13: Leova | D13: Filipeni | E13: =SUMIF(Individual!A:A,JSON!A13,Individual!I:I) -> 3986 | F13: =AVERAGEIF(Individual!A:A,JSON!A13,Individual!H:H) -> 16.9 | G13: =SUMIF(Individual!A:A,JSON!A13,Individual!J:J) -> 123.825 | H13: =SUMIF(Individual!A:A,JSON!A13,Individual!K:K) -> 3 | I13: =SUMIF(Individual!A:A,JSON!A13,Individual!L:L) -> 4 | J13: Cupcui; Filipeni; Romanovca; Sărata Noua | K13: PAS;PSRM | L13: PAS;PSRM | M13: https://www.moldpres.md/rom/politica/grupuri-de-primarii-amalgamate-au-fost-create-in-toate-regiunile-tarii-investitii-de-366-de-milioane-de-lei-planificate-de-guvern-pentru-modernizarea-localitatilor
A14: 2026-13 | B14: Soroca/Dondușeni-01 | C14: Soroca/Dondușeni | D14: Visoca | E14: =SUMIF(Individual!A:A,JSON!A14,Individual!I:I) -> 4157 | F14: =AVERAGEIF(Individual!A:A,JSON!A14,Individual!H:H) -> 18.4 | G14: =SUMIF(Individual!A:A,JSON!A14,Individual!J:J) -> 145.796 | H14: =SUMIF(Individual!A:A,JSON!A14,Individual!K:K) -> 5 | I14: =SUMIF(Individual!A:A,JSON!A14,Individual!L:L) -> 5 | J14: Dărcăuți; Teleșeuca; Crișcuți; Visoca; Rudi | K14: PAS;PSRM;DA | L14: PAS;PSRM;DA | M14: https://www.moldpres.md/rom/politica/grupuri-de-primarii-amalgamate-au-fost-create-in-toate-regiunile-tarii-investitii-de-366-de-milioane-de-lei-planificate-de-guvern-pentru-modernizarea-localitatilor
A15: 2026-14 | B15: Ialoveni-01 | C15: Ialoveni | D15: Costești | E15: =SUMIF(Individual!A:A,JSON!A15,Individual!I:I) -> 9261 | F15: =AVERAGEIF(Individual!A:A,JSON!A15,Individual!H:H) -> 36 | G15: =SUMIF(Individual!A:A,JSON!A15,Individual!J:J) -> 76.307 | H15: =SUMIF(Individual!A:A,JSON!A15,Individual!K:K) -> 1 | I15: =SUMIF(Individual!A:A,JSON!A15,Individual!L:L) -> 1 | J15: Costești; Hansca | K15: PAS;PSDE | L15: PAS;PSDE | M15: https://www.moldpres.md/rom/politica/grupuri-de-primarii-amalgamate-au-fost-create-in-toate-regiunile-tarii-investitii-de-366-de-milioane-de-lei-planificate-de-guvern-pentru-modernizarea-localitatilor
A16: 2026-15 | B16: Hîncești-06 | C16: Hîncești | D16: Mingir | E16: =SUMIF(Individual!A:A,JSON!A16,Individual!I:I) -> 4366 | F16: =AVERAGEIF(Individual!A:A,JSON!A16,Individual!H:H) -> 17.4 | G16: =SUMIF(Individual!A:A,JSON!A16,Individual!J:J) -> 103.821 | H16: =SUMIF(Individual!A:A,JSON!A16,Individual!K:K) -> 1 | I16: =SUMIF(Individual!A:A,JSON!A16,Individual!L:L) -> 2 | J16: Mingir; Voinescu | K16: PAS | L16: PAS;PSDE | M16: https://www.facebook.com/share/r/1EMYQxZcAn/
A17: 2026-16 | B17: Soroca-03 | C17: Soroca | D17: Căinarii Vechi | E17: =SUMIF(Individual!A:A,JSON!A17,Individual!I:I) -> 4113 | F17: =AVERAGEIF(Individual!A:A,JSON!A17,Individual!H:H) -> 17 | G17: =SUMIF(Individual!A:A,JSON!A17,Individual!J:J) -> 141.67 | H17: =SUMIF(Individual!A:A,JSON!A17,Individual!K:K) -> 2 | I17: =SUMIF(Individual!A:A,JSON!A17,Individual!L:L) -> 3 | J17: Bulboci; Căinarii Vechi; Vădeni | K17: PAS;PSRM | L17: PAS;PSRM | M17: https://www.facebook.com/share/r/1EMYQxZcAn/

Sheet Populations
A1: Raion_Name | B1: LPA_Name | C1: Cuatm | D1: Population (2024 Census) | E1: Percentage change 2024-2014 | F1: Pop_2024 | G1: In Cluster
A2: mun. Chișinău | B2: Consiliul Municipal Chișinău | C2: 0100 | D2: 5. > 10K | E2: 0.67228876 | F2: 567038 | G2: =IFERROR(VLOOKUP(C2,Individual!$B$2:$B$48,1,FALSE),FALSE) -> FALSE
A3: mun. Bălți | B3: Consiliul Municipal Bălți | C3: 0300 | D3: 5. > 10K | E3: -0.071234555 | F3: 90954 | G3: =IFERROR(VLOOKUP(C3,Individual!$B$2:$B$48,1,FALSE),FALSE) -> FALSE
A4: Ungheni | B4: Ungheni | C4: 9201 | D4: 5. > 10K | E4: -0.14111804 | F4: 26457 | G4: =IFERROR(VLOOKUP(C4,Individual!$B$2:$B$48,1,FALSE),FALSE) -> FALSE
A5: mun. Chișinău | B5: Durlești | C5: 0121 | D5: 5. > 10K | E5: 0.52864614 | F5: 26308 | G5: =IFERROR(VLOOKUP(C5,Individual!$B$2:$B$48,1,FALSE),FALSE) -> FALSE
A6: Cahul | B6: Cahul | C6: 1701 | D6: 5. > 10K | E6: -0.25967753 | F6: 22223 | G6: =IFERROR(VLOOKUP(C6,Individual!$B$2:$B$48,1,FALSE),FALSE) -> FALSE
A7: Orhei | B7: Orhei | C7: 6401 | D7: 5. > 10K | E7: 0.053073819 | F7: 22183 | G7: =IFERROR(VLOOKUP(C7,Individual!$B$2:$B$48,1,FALSE),FALSE) -> FALSE
A8: Soroca | B8: Soroca | C8: 7801 | D8: 5. > 10K | E8: -0.047801406 | F8: 21135 | G8: =IFERROR(VLOOKUP(C8,Individual!$B$2:$B$48,1,FALSE),FALSE) -> FALSE
A9: UTA Găgăuzia | B9: municipiul Comrat | C9: 9601 | D9: 5. > 10K | E9: -0.049371054 | F9: 19120 | G9: =IFERROR(VLOOKUP(C9,Individual!$B$2:$B$48,1,FALSE),FALSE) -> FALSE
A10: mun. Chișinău | B10: Codru | C10: 0131 | D10: 5. > 10K | E10: 0.1491151 | F10: 18310 | G10: =IFERROR(VLOOKUP(C10,Individual!$B$2:$B$48,1,FALSE),FALSE) -> FALSE
A11: Ialoveni | B11: Ialoveni | C11: 5501 | D11: 5. > 10K | E11: 0.17179385 | F11: 14665 | G11: =IFERROR(VLOOKUP(C11,Individual!$B$2:$B$48,1,FALSE),FALSE) -> 5501
A12: Strășeni | B12: Bucovăț | C12: 8002 | D12: 1. < 1500 | E12: -0.33541537 | F12: 1064 | G12: =IFERROR(VLOOKUP(C12,Individual!$B$2:$B$48,1,FALSE),FALSE) -> FALSE
A13: UTA Găgăuzia | B13: municipiul Ceadir-Lunga | C13: 9602 | D13: 5. > 10K | E13: -0.13971695 | F13: 14285 | G13: =IFERROR(VLOOKUP(C13,Individual!$B$2:$B$48,1,FALSE),FALSE) -> FALSE
... A35: Ialoveni | B35: Costești | C35: 5515 | D35: 4. 5K - 10K | E35: -0.22737691 | F35: 8427 | G35: =IFERROR(VLOOKUP(C35,Individual!$B$2:$B$48,1,FALSE),FALSE) -> 5515
A36: Leova | B36: Leova (Merged) | C36: 9999 | D36: 4. 5K - 10K | F36: 8344 | G36: =IFERROR(VLOOKUP(C36,Individual!$B$2:$B$48,1,FALSE),FALSE) -> FALSE
A37: UTA Găgăuzia | B37: Congaz | C37: 9622 | D37: 4. 5K - 10K | E37: -0.25658545 | F37: 8269 | G37: =IFERROR(VLOOKUP(C37,Individual!$B$2:$B$48,1,FALSE),FALSE) -> FALSE
A38: mun. Chișinău | B38: Grătiești | C38: 0155 | D38: 4. 5K - 10K | E38: 0.18049491 | F38: 7299 | G38: =IFERROR(VLOOKUP(C38,Individual!$B$2:$B$48,1,FALSE),FALSE) -> FALSE
A39: Glodeni | B39: Glodeni | C39: 4801 | D39: 4. 5K - 10K | E39: -0.1604426 | F39: 7284 | G39: =IFERROR(VLOOKUP(C39,Individual!$B$2:$B$48,1,FALSE),FALSE) -> FALSE
A40: mun. Chișinău | B40: Ciorescu | C40: 0152 | D40: 4. 5K - 10K | E40: 0.12632109 | F40: 6714 | G40: =IFERROR(VLOOKUP(C40,Individual!$B$2:$B$48,1,FALSE),FALSE) -> FALSE
A41: UTA Găgăuzia | B41: Copceac | C41: 9626 | D41: 4. 5K - 10K | E41: -0.2959072 | F41: 6434 | G41: =IFERROR(VLOOKUP(C41,Individual!$B$2:$B$48,1,FALSE),FALSE) -> FALSE
A42: Leova | B42: Leova | C42: 5701 | D42: 4. 5K - 10K | E42: -0.14093779 | F42: 6394 | G42: =IFERROR(VLOOKUP(C42,Individual!$B$2:$B$48,1,FALSE),FALSE) -> FALSE
A43: Basarabeasca | B43: Basarabeasca | C43: 1201 | D43: 4. 5K - 10K | E43: -0.2573486 | F43: 6291 | G43: =IFERROR(VLOOKUP(C43,Individual!$B$2:$B$48,1,FALSE),FALSE) -> FALSE
A44: Orhei | B44: Peresecina | C44: 6453 | D44: 4. 5K - 10K | E44: -0.22262027 | F44: 6076 | G44: =IFERROR(VLOOKUP(C44,Individual!$B$2:$B$48,1,FALSE),FALSE) -> FALSE
A45: Dondușeni | B45: Orașul Dondușeni | C45: 3401 | D45: 4. 5K - 10K | E45: -0.15687931 | F45: 5987 | G45: =IFERROR(VLOOKUP(C45,Individual!$B$2:$B$48,1,FALSE),FALSE) -> FALSE
A46: Criuleni | B46: Criuleni | C46: 3101 | D46: 4. 5K - 10K | E46: -0.12880143 | F46: 5844 | G46: =IFERROR(VLOOKUP(C46,Individual!$B$2:$B$48,1,FALSE),FALSE) -> FALSE
A47: Briceni | B47: Briceni | C47: 1401 | D47: 4. 5K - 10K | E47: -0.20905113 | F47: 5785 | G47: =IFERROR(VLOOKUP(C47,Individual!$B$2:$B$48,1,FALSE),FALSE) -> FALSE
A48: Telenești | B48: Telenești | C48: 8901 | D48: 4. 5K - 10K | E48: -0.21544209 | F48: 5670 | G48: =IFERROR(VLOOKUP(C48,Individual!$B$2:$B$48,1,FALSE),FALSE) -> FALSE
... A101: Sîngerei | B101: Sîngereii Noi | C101: 7469 | D101: 3. 3K - 5K | E101: -0.36880125 | F101: 3233 | G101: =IFERROR(VLOOKUP(C101,Individual!$B$2:$B$48,1,FALSE),FALSE) -> FALSE
A102: Fălești | B102: Călinești (Merged) | C102: 9998 | D102: 3. 3K - 5K | F102: 3219 | G102: =IFERROR(VLOOKUP(C102,Individual!$B$2:$B$48,1,FALSE),FALSE) -> FALSE
A103: Nisporeni | B103: Vărzăreşti | C103: 6052 | D103: 3. 3K - 5K | E103: -0.38153075 | F103: 3208 | G103: =IFERROR(VLOOKUP(C103,Individual!$B$2:$B$48,1,FALSE),FALSE) -> FALSE
A104: Ungheni | B104: Petrești | C104: 9259 | D104: 3. 3K - 5K | E104: -0.21234074 | F104: 3153 | G104: =IFERROR(VLOOKUP(C104,Individual!$B$2:$B$48,1,FALSE),FALSE) -> FALSE
A105: Ungheni | B105: Măcărești | C105: 9244 | D105: 3. 3K - 5K | E105: -0.2495229 | F105: 3146 | G105: =IFERROR(VLOOKUP(C105,Individual!$B$2:$B$48,1,FALSE),FALSE) -> FALSE
A106: Ialoveni | B106: Mileștii Mici | C106: 5521 | D106: 3. 3K - 5K | E106: -0.3688871 | F106: 3136 | G106: =IFERROR(VLOOKUP(C106,Individual!$B$2:$B$48,1,FALSE),FALSE) -> FALSE
A107: Căușeni | B107: Sălcuța | C107: 2721 | D107: 3. 3K - 5K | E107: -0.28348624 | F107: 3124 | G107: =IFERROR(VLOOKUP(C107,Individual!$B$2:$B$48,1,FALSE),FALSE) -> FALSE
A108: Ialoveni | B108: Ţipala | C108: 5531 | D108: 3. 3K - 5K | E108: -0.27266355 | F108: 3113 | G108: =IFERROR(VLOOKUP(C108,Individual!$B$2:$B$48,1,FALSE),FALSE) -> FALSE
A109: Anenii Noi | B109: Chetrosu | C109: 1017 | D109: 3. 3K - 5K | E109: -0.20655822 | F109: 3073 | G109: =IFERROR(VLOOKUP(C109,Individual!$B$2:$B$48,1,FALSE),FALSE) -> FALSE
A110: Strășeni | B110: Cojuşna | C110: 8015 | D110: 4. 5K - 10K | E110: -0.16199776 | F110: 5235 | G110: =IFERROR(VLOOKUP(C110,Individual!$B$2:$B$48,1,FALSE),FALSE) -> FALSE
A111: Dubăsari | B111: Cocieri | C111: 3810 | D111: 3. 3K - 5K | E111: -0.21029601 | F111: 3068 | G111: =IFERROR(VLOOKUP(C111,Individual!$B$2:$B$48,1,FALSE),FALSE) -> FALSE
A112: Căușeni | B112: Zaim | C112: 2731 | D112: 3. 3K - 5K | E112: -0.28404578 | F112: 3065 | G112: =IFERROR(VLOOKUP(C112,Individual!$B$2:$B$48,1,FALSE),FALSE) -> FALSE
A113: Anenii Noi | B113: Floreni | C113: 1027 | D113: 3. 3K - 5K | E113: -0.23005286 | F113: 3059 | G113: =IFERROR(VLOOKUP(C113,Individual!$B$2:$B$48,1,FALSE),FALSE) -> FALSE
...

Sheet Area
A1: wkt_geom | B1: gfullname | C1: name | D1: cuatm | E1: Cuatm-text | F1: area_km2
A2: MultiPolygon (((191199.47219999998924322 156127.12040000001434237, 191200.75979999999981374 156092.57620000001043081, 191200.75979999999981374 156029.280399999988731, 191199.99640000000363216 155919.7021999999997206, 191199.57660000000032596 155840.9165999999968335, 191195.80400000000372529 155671.90200000000186265, 191198.00760000001173466 155534.51060000000870787, 191193.87599999998928979 155258.46059999999124557, 191196.85060000000521541 155211.96559999999590218, 191200.29360000000451691 155189.9023999999917578, 191198.52559999999357387 155045.39780000000610016, 191193.80559999999240972 154923.09799999999813735, 191190.3720000000030268 154800.79819999999017455, 191188.22640000001410954 154681.07320000001345761, 191186.51039999999920838 154461.36259999999310821, 191182.64799999998649582 154291.85939999998663552, 191183.50640000001294538 154076.86919999998644926, 191230.63860000000568107 154054.89000000001396984, 191288.43780000001424924 153993.68020000000251457, 191583.87739999999757856 153990.61559999999008141, 191861.04019999998854473 153990.58480000001145527, 192017.29099999999743886 153994.47779999999329448, 192531.80819999999948777 154017.65040000001317821, 192579.01139999998849817 154023.22899999999208376, 192629.21859999999287538 154036.10260000001289882, 192701.48379999998724088 154048.21179999999003485, 192741.1780000000144355 154068.92019999999320135, 192873.56140000000596046 154137.98459999999613501, 192927.25560000000405125 154296.70240000000922009, 193095.5530000000144355 154245.181799999991199, 193114.29680000001098961 153589.76560000001336448, 193127.99460000000544824 153518.12059999999473803, 193145.23459999999613501 153480.90260000000125729, 193168.62179999999352731 153430.69539999999688007, 193194.5834000000031665 153377.91339999999036081, 193228.05499999999301508 153326.20420000000740401, 193228.91339999999036081 153319.12380000000121072, 193237.28099999998812564 153283.93559999999706633, 193248.65299999999115244 153247.24580000000423752, 193278.23759999999310821 153177.84419999999227002, 193303.61360000001150183 153088.58100000000558794, 193304.67339999999967404 153084.85320000001229346, 193308.5273999999917578 153071.29699999999138527, 193317.29879999998956919 152993.43859999999403954, 193338.22159999998984858 152805.02700000000186265, 193344.16479999999864958 152733.16000000000349246, 193355.27540000001317821 152663.5620000000053551, 193379.59280000001308508 152561.89100000000325963, 193380.05999999999767169 152560.48600000000442378, 193381.25119999999878928 152556.90400000000954606, 193465.75159999998868443 152302.78520000001299195, 193474.69680000000516884 152272.24299999998765998, 193501.38879999998607673 152181.72860000000218861, 193536.1454000000085216 152063.57139999998616986, 193563.05119999998714775 151967.73360000000684522, 193574.41719999999622814 151934.0620000000053551, 193244.2114000000001397 151856.16180000000167638, 193213.56560000000172295 151848.7417999999888707, 193210.15580000000772998 151846.66320000000996515, 193114.22459999998682179 151821.46419999998761341, 192905.10300000000279397 151763.89519999999902211, 192829.95040000000153668 151728.16320000000996515, 192545.55059999998775311 151543.40340000001015142, 192386.34520000001066364 151441.97599999999511056, 192345.33139999999548309 151411.61100000000442378, 191860.82560000001103617 150942.78740000000107102, 191860.75839999999152496 150926.03219999998691492, 191900.02319999999599531 150800.51420000000507571, 191959.24199999999837019 150603.97620000000461005, 192007.30360000001383014 150460.4347999999881722, 192065.87880000000586733 150265.82779999999911524, 192104.07079999998677522 150145.24460000000544824, 192142.04800000000977889 150025.09039999998640269, 192173.58859999998821877 149930.25440000000526197, 192217.14459999999962747 149781.77799999999115244, 192230.2325999999884516 149729.85440000001108274, 192257.91099999999278225 149645.31719999999040738, 192295.88819999998668209 149523.66120000000228174, 192328.93059999999240972 149409.3000000000174623, 192353.39060000001336448 149329.69779999999445863, 192398.87779999998747371 149190.23319999998784624, 192448.65580000000772998 149038.10940000001573935, 192487.92040000000270084 148928.03959999998915009, 192523.10839999999734573 148823.76300000000628643, 192572.88680000000749715 148649.53919999999925494, 192608.93280000000959262 148528.95600000000558794, 192655.92199999999138527 148387.77480000001378357, 192670.81779999998980202 148337.63939999998547137, 192687.58540000001084991 148284.43059999999240972, 192702.11699999999837019 148240.38819999998668209, 192727.44719999999506399 148164.37059999999473803, 192745.04199999998672865 148112.50860000000102445, 192643.69200000001001172 148096.61540000000968575, 192520.96239999998942949 148074.51560000001336448, 192441.57519999999203719 148062.71479999998700805, 192376.77799999999115244 148054.34700000000884756, 192311.76620000001275912 148047.26639999999315478, 192268.63899999999557622 148047.26639999999315478, 192216.71539999998640269 148049.84119999999529682, 192157.06739999999990687 148058.20900000000256114, 192051.50359999999636784 148067.0059999999939464, 191959.02760000000125729 148057.3508000000147149, 191937.1424000000115484 148046.62280000001192093, 191928.68040000001201406 148033.10800000000745058, 191927.27239999998710118 148017.22800000000279397, 191953.44880000001285225 147907.58720000000903383, 191965.68280000000959262 147862.81440000000293367, 191972.72640000001410954 147835.43319999999948777, 191956.21379999999771826 147825.73079999999026768, 191921.75620000000344589 147833.04079999998793937, 191868.97419999999692664 147844.41260000001057051, 191807.82360000000335276 147849.99119999998947605, 191758.90400000000954606 147858.35899999999674037, 191660.20600000000558794 147872.9492000000027474, 191610.85699999998905696 147880.67339999999967404, 191598.19779999999445863 147877.24040000000968575, 191588.97219999998924322 147868.44339999998919666, 191576.09779999998863786 147861.79199999998672865, 191563.65380000000004657 147862.22119999999995343, 191534.04420000000391155 147874.45120000001043081, 191510.87179999999352731 147878.098599999997532, 191490.91740000000572763 147878.098599999997532, 191462.38060000000405125 147884.10620000000926666, 191419.46859999999287538 147887.53919999999925494, 191379.56020000000717118 147888.18299999998998828, 191366.47179999999934807 147887.96840000001247972, 191357.67499999998835847 147889.04120000000693835, 191349.73620000001392327 147891.6157999999995809, 191343.51379999998607673 147894.6197999999858439, 191334.50219999998807907 147898.91099999999278225, 191324.84700000000884756 147902.77299999998649582, 191313.9046000000089407 147905.56239999999525025, 191293.73579999999492429 147908.13699999998789281, 191260.26439999998547137 147912.42840000000433065, 191222.07240000000456348 147916.719600000011269, 191118.86840000000665896 147928.73499999998603016, 191049.77999999999883585 147937.10279999999329448, 190985.62619999999878928 147943.96880000000237487, 190983.69519999998738058 147943.21799999999348074, 190980.69120000000111759 147928.8423999999940861, 190968.47640000001410954 147835.00760000001173466, 190950.0089999999909196 147663.64459999999962747, 190935.41860000000451691 147545.85060000000521541, 190922.97419999999692664 147417.75779999999213032, 190918.03940000000875443 147371.41260000001057051, 190907.52580000000307336 147277.86400000000139698, 190891.86259999999310821 147129.38759999998728745, 190887.78620000000228174 147080.46780000001308508, 190877.48699999999371357 146998.07639999999082647, 190875.77059999998891726 146977.47839999999268912, 190875.34140000000479631 146965.67759999999543652, 190871.90859999999520369 146951.51660000000265427, 190867.18820000000414439 146934.56620000000111759, 190865.47179999999934807 146924.05280000000493601, 190865.68619999999646097 146912.89559999998891726, 190867.18820000000414439 146901.09479999999166466, 190867.61739999998826534 146891.22500000000582077, 190864.61340000000200234 146865.69219999999040738, 190853.02720000001136214 146756.90979999999399297, 190842.94279999998980202 146645.76699999999254942, 190839.51000000000931323 146611.22279999998863786, 190834.36040000000502914 146575.17639999999664724, 190825.99280000000726432 146506.94599999999627471, 190821.48680000001331791 146457.38240000000223517, 190815.9083999999857042 146395.15979999999399297, 190812.47519999998621643 146353.32019999998738058, 190806.06719999999040738 146284.11300000001210719, 190801.77600000001257285 146263.94419999999809079, 190801.47779999999329448 146255.51840000000083819, 190444.91419999999925494 146400.34320000000298023, 190441.35560000000987202 146401.00640000001294538, 190444.71499999999650754 146375.55019999999785796, 190449.79019999998854473 146337.09359999999287538, 190480.60039999999571592 146158.62340000001131557, 190483.01660000000265427 146145.25640000001294538, 190500.12479999999050051 146050.39879999999538995, 190505.56320000000414439 146020.2856000000028871, 190544.94740000000456348 145801.97140000000945292, 190555.39400000000023283 145709.99419999998644926, 190524.12779999998747371 145707.56539999999222346, 190515.98000000001047738 145704.26180000000749715, 190491.94959999999264255 145698.68299999998998828, 190460.19440000000759028 145696.9666000000142958, 190413.84880000000703149 145694.39180000001215376, 190373.94080000001122244 145693.53340000001480803, 190348.19380000000819564 145697.50279999998747371, 190335.32019999998738058 145698.79039999999804422, 190332.74499999999534339 145692.35360000000218861, 190336.17780000000493601 145635.70920000001206063, 190336.88120000000344589 145449.37340000001131557, 190027.63839999999618158 145407.73819999999250285, 189867.14819999999599531 145384.99460000000544824, 189629.84260000000358559 145355.81419999999343418, 189442.31640000001061708 145334.35819999998784624, 189331.17399999999906868 145318.90979999999399297, 189190.77820000000065193 145305.29699999999138527, 189153.85819999998784624 145305.49040000000968575, 189107.25179999999818392 145298.99340000000665896, 189070.07959999999729916 145293.81159999998635612, 189059.0597999999881722 145389.5597999999881722, 189052.55919999998877756 145422.28239999999641441, 189043.08400000000256114 145459.63240000000223517, 189031.03020000000833534 145490.77880000000004657, 189020.73099999999976717 145504.51060000000870787, 189006.14060000001336448 145516.09700000000884756, 188990.26380000001518056 145523.8212000000057742, 188969.66539999999804422 145528.11240000001271255, 188933.1902000000118278 145529.39980000001378357, 188864.95980000001145527 145525.53760000001057051, 188795.87100000001373701 145517.81340000001364388, 188693.38000000000465661 145503.92360000000917353, 188605.76939999999012798 145494.21179999999003485, 188554.27499999999417923 145491.63699999998789281, 188503.63899999999557622 145491.20780000000377186, 188463.71479999998700805 145491.69380000000819564, 188419.09280000001308508 145494.44820000001345761, 188360.3120000000053551 145498.93200000000069849, 188262.47200000000884756 145510.51840000000083819, 188183.51360000000568107 145521.67559999998775311, 188116.14160000000265427 145525.53760000001057051, 188017.01380000001518056 145524.25020000000949949, 187960.3697999999858439 145517.3842000000004191, 187927.32740000000922009 145510.5181999999913387, 187904.5082000000111293 145510.64420000000973232, 187888.53239999999641441 145513.39860000001499429, 187872.66680000000633299 145523.53479999999399297, 187860.2166000000142958 145534.22200000000884756, 187847.08179999998537824 145547.85180000000400469, 187833.35019999998621643 145566.73319999998784624, 187815.48439999998663552 145601.43020000000251457, 187801.594600000011269 145637.53839999999036081, 187787.00500000000465661 145678.73420000000623986, 187774.1309999999939464 145734.09100000001490116, 187762.97419999999692664 145794.59719999998924322, 187747.39420000000973232 145885.68780000001424924, 187736.79740000001038425 145946.93559999999706633, 187721.77820000000065193 146002.72140000000945292, 187711.69640000001527369 146047.6484000000054948, 187711.03520000001299195 146071.22640000001410954, 187714.34059999999590218 146090.61759999999776483, 187722.8242000000027474 146104.5, 187730.97740000000339933 146112.54300000000512227, 187742.76639999999315478 146121.35719999999855645, 187764.36120000001392327 146130.17139999999199063, 187791.68520000000717118 146140.30760000000009313, 187811.03580000001238659 146150.33960000000661239, 187889.56500000000232831 146210.84580000001005828, 187956.07899999999790452 146273.06839999998919666, 188098.11840000000665896 146408.67079999999259599, 188141.5082000000111293 146442.69239999999990687, 188181.05239999998593703 146471.50080000000889413, 188261.86759999999776483 146528.46259999999892898, 188335.46619999999529682 146577.60180000000400469, 188428.34580000001005828 146627.84260000000358559, 188486.73999999999068677 146655.82779999999911524, 188532.07800000000861473 146671.80340000000433065, 188566.34320000000298023 146681.05840000000898726, 188623.96619999999529682 146689.98279999999795109, 188692.71700000000419095 146699.0174000000115484, 188749.56859999999869615 146711.2470000000030268, 188811.74840000001131557 146731.37080000000423752, 188871.82519999999203719 146755.4016000000119675, 188924.47560000000521541 146784.40479999998933636, 188965.37400000001071021 146812.90400000000954606, 188999.1757999999972526 146847.64660000000731088, 189028.88440000000991859 146881.56359999999403954, 189055.48920000001089647 146924.47599999999511056, 189085.8304000000061933 146987.5719999999855645, 189103.84440000000176951 147034.61759999999776483, 189117.61639999999897555 147074.94260000000940636, 189123.29079999998793937 147115.0059999999939464, 189123.29079999998793937 147142.469600000011269, 189117.78159999998752028 147164.84719999998924322, 189103.55040000000735745 147187.098599999997532, 189087.74559999999473803 147204.87959999998565763, 189059.00239999999757856 147228.32560000001103617, 189033.93619999999646097 147240.75940000000991859, 188989.64480000000912696 147257.28599999999278225, 188958.79500000001280569 147265.21880000000237487, 188913.29180000000633299 147272.27019999999902211, 188863.6015999999945052 147272.93119999999180436, 188805.64819999999599531 147264.99840000001131557, 188772.92540000000735745 147259.26920000000973232, 188712.21760000000358559 147252.65840000001480803, 188628.70300000000861473 147249.13279999999213032, 188491.31140000000596046 147248.69200000001001172, 188363.28500000000349246 147251.99720000001252629, 188279.63659999999799766 147261.76579999999376014, 188201.53580000001238659 147277.21419999998761341, 188170.91479999999864958 147290.33900000000721775, 188156.04939999998896383 147300.38680000000749715, 188140.94640000001527369 147320.5273999999917578, 188134.5560000000114087 147341.0204000000085216, 188130.42439999998896383 147361.84400000001187436, 188132.35240000000339933 147384.32019999998738058, 188139.78940000000875443 147406.02520000000367872, 188156.97700000001350418 147428.72159999998984858, 188188.2674000000115484 147455.82519999999203719, 188251.31500000000232831 147494.35019999998621643, 188423.82079999998677522 147572.45019999999203719, 188535.27160000000731088 147625.82899999999790452, 188549.98399999999674037 147646.2592000000004191, 188555.13279999999213032 147662.5659999999916181, 188552.556799999991199 147682.30559999999240972, 188543.1167999999888707 147701.18679999999585561, 188531.1008000000147149 147714.9188000000140164, 188506.2143999999971129 147732.94200000001001172, 188473.60000000000582077 147748.39040000000386499, 188416.95679999998537824 147767.27160000000731088, 188319.97440000000642613 147799.02679999999236315, 188222.99199999999837019 147838.5059999999939464, 188171.68499999999767169 147871.30400000000372529, 188140.39459999999962747 147896.42439999998896383, 188117.91820000001462176 147921.10420000000158325, 188098.30660000001080334 147951.07240000000456348, 188080.6780000000144355 147998.66899999999441206, 188073.84700000000884756 148042.51959999999962747, 188071.0834000000031665 148101.12859999999636784, 188072.80019999999785796 148156.05640000000130385, 188084.81460000001243316 148260.76199999998789281, 188093.39699999999720603 148331.13819999998668209, 188100.17900000000372529 148359.16940000001341105, 188107.98740000001271255 148380.91620000000693835, 188115.71220000000903383 148398.08139999999548309, 188130.80819999999948777 148424.83499999999185093, 188154.16579999998793937 148448.41300000000046566, 188181.04920000000856817 148474.52499999999417923, 188199.82099999999627471 148501.9287999999942258, 188210.11859999998705462 148531.10899999999674037, 188218.01360000000568107 148581.28680000000167638, 188216.125 148625.51579999999376014, 188204.11220000000321306 148691.60060000000521541, 188190.37779999998747371 148731.93820000000414439, 188171.49780000001192093 148767.12619999999878928, 188147.4673999999940861 148804.88860000000568107, 188118.28659999999217689 148838.3598000000056345, 188061.64340000000083819 148893.28839999999036081, 187983.54099999999743886 148980.82920000000740401, 187933.76500000001396984 149025.45759999999427237, 187840.54420000000391155 149098.23879999999189749, 187799.87859999999636784 149117.28959999998915009, 187771.55540000001201406 149119.00640000001294538, 187750.58400000000256114 149118.29099999999743886, 187726.0689999999885913 149110.42399999999906868, 187690.8802000000141561 149091.54240000000572763, 187652.25940000000991859 149059.78800000000046566, 187603.3393999999971129 149010.00959999999031425, 187558.76500000001396984 148949.27900000000954606, 187443.70800000001327135 148752.53620000000228174, 187420.53359999999520369 148715.63159999999334104, 187407.87719999998807907 148701.26959999999962747, 187397.36240000001271255 148690.74259999999776483, 187390.35899999999674037 148687.38740000000689179, 187378.68020000000251457 148685.51439999998547137, 187367.11139999999431893 148685.29399999999441206, 187355.76319999998668209 148687.38740000000689179, 187340.71600000001490116 148692.45900000000256114, 187319.26000000000931323 148704.47440000000642613, 187259.79839999999967404 148752.28179999999701977, 187172.50159999998868443 148804.88920000000507571, 187091.82639999999082647 148853.80879999999888241, 187030.03279999998630956 148883.8476000000082422, 186956.22320000000763685 148907.87839999998686835, 186794.87440000000060536 148959.37320000000181608, 186708.02840000001015142 148985.52700000000186265, 186653.26319999998668209 149004.86000000001513399, 186625.8007999999972526 149017.73360000000684522, 186600.05199999999604188 149034.8984000000054948, 186575.98040000000037253 149055.37940000000526197, 186552.62260000000242144 149080.94039999999222346, 186539.89699999999720603 149108.04420000000391155, 186536.54320000001462176 149126.73079999999026768, 186536.8120000000053551 149152.11499999999068677, 186541.76999999998952262 149174.92180000001098961, 186551.99119999998947605 149198.82320000001345761, 186578.59700000000884756 149234.86939999999594875, 186610.35120000000461005 149271.77400000000488944, 186642.96559999999590218 149297.5211999999883119, 186741.66320000000996515 149366.18080000000190921, 186859.2417999999888707 149432.26540000000386499, 186967.38159999999334104 149495.77559999999357387, 187060.93040000001201406 149538.6879999999946449, 187096.11759999999776483 149560.14400000000023283, 187104.70000000001164153 149574.73420000000623986, 187107.27600000001257285 149590.18260000000009313, 187103.8423999999940861 149610.780399999988731, 187097.83280000000377186 149627.08720000000903383, 187078.95240000000922009 149655.40899999998509884, 187042.90599999998812564 149698.32140000001527369, 186987.9795999999914784 149759.25700000001234002, 186942.49160000000847504 149813.32579999999143183, 186885.8483999999880325 149898.29219999999622814, 186854.09200000000419095 149966.95180000000982545, 186840.36079999999492429 150007.28940000000875443, 186830.92079999999259599 150051.91779999999562278, 186827.48720000000321306 150112.85339999999268912, 186828.34479999999166466 150176.36340000000200234, 186830.92079999999259599 150202.96900000001187436, 186843.79440000001341105 150275.9198000000033062, 186854.09200000000419095 150326.55619999999180436, 186873.83280000000377186 150390.06620000000111759, 186893.5719999999855645 150444.13539999999920838, 186919.31919999999809079 150519.66120000000228174, 186950.2166000000142958 150598.6197999999858439, 186983.68719999998575076 150673.28700000001117587, 187002.57039999999688007 150725.63980000000447035, 187014.58319999999366701 150766.83540000001084991, 187012.86799999998765998 150794.29899999999906868, 187007.71919999999227002 150815.75580000001355074, 186990.55439999999362044 150834.63659999999799766, 186957.08240000001387671 150845.79420000000391155, 186914.17019999999320135 150851.80139999999664724, 186863.53359999999520369 150856.09260000000358559, 186796.75659999999334104 150849.17459999999846332, 186695.31620000000111759 150830.3453999999910593, 186624.08379999999306165 150808.88939999998547137, 186558.85740000000805594 150795.15739999999641441, 186528.8189999999885913 150791.72459999998682179, 186505.47599999999511056 150795.79399999999441206, 186495.81359999999403954 150802.42960000000311993, 186478.181799999991199 150811.46419999998761341, 186456.7258000000147149 150838.06979999999748543, 186443.36780000000726432 150860.86160000000381842, 186430.11939999999594875 150894.71379999999771826, 186423.25380000000586733 150923.03580000001238659, 186423.25419999999576248 150976.24720000001252629, 186427.54519999999320135 151028.60000000000582077, 186431.83660000000963919 151104.12559999999939464, 186433.55340000000433065 151196.8159999999916181, 186430.9788000000116881 151295.51399999999557622, 186412.80179999998654239 151436.57159999999566935, 186386.03500000000349246 151575.96059999999124557, 186369.18520000000717118 151617.35540000000037253, 186340.86340000000200234 151665.41639999998733401, 186317.69080000001122244 151702.32180000000516884, 186293.13519999998970889 151715.98519999999552965, 186283.3000000000174623 151717.78200000000651926, 186251.60440000001108274 151717.76980000000912696, 186215.36199999999371357 151705.5976000000082422, 186164.9228000000002794 151663.70100000000093132, 186111.71160000000963919 151605.34020000000600703, 186060.21720000001369044 151526.38180000000284053, 186026.74520000000484288 151457.72219999998924322, 185987.2651999999943655 151365.89000000001396984, 185957.22680000000400469 151273.19959999999264255, 185935.77079999999841675 151240.5864000000001397, 185912.59799999999813735 151223.42139999999199063, 185884.276400000002468 151209.68960000001243316, 185854.23800000001210719 151199.39060000001336448, 185808.75159999998868443 151198.53239999999641441, 185746.09940000000642613 151207.11499999999068677, 185698.03800000000046566 151216.55540000001201406, 185648.26039999999920838 151223.42139999999199063, 185569.30119999998714775 151220.84679999999934807, 185532.39720000000670552 151227.71259999999892898, 185510.94120000000111759 151245.73579999999492429, 185497.20920000001206063 151269.76660000000265427, 185488.62679999999818392 151298.9469999999855645, 185487.76840000000083819 151335.85140000001410954, 185494.6339999999909196 151371.89780000000610016, 185499.78359999999520369 151392.49559999999473803, 185533.17079999999259599 151435.31739999999990687, 185591.75779999999213032 151482.36300000001210719, 185654.26680000001215376 151518.65739999999641441, 185742.66680000000633299 151556.42019999999320135, 185779.57079999998677522 151579.59299999999348074, 185798.45240000000922009 151601.04899999999906868, 185813.04279999999562278 151622.50500000000465661, 185819.90840000001480803 151642.24499999999534339, 185819.90840000001480803 151672.2833999999857042, 185812.18359999998938292 151695.4561999999859836, 185804.46040000001084991 151710.04579999999259599, 185778.71319999999832362 151734.07699999999022111, 185735.80119999998714775 151767.54819999999017455, 185659.41719999999622814 151816.46820000000298023, 185599.34039999998640269 151849.08180000001448207, 185527.24799999999231659 151879.54839999999967404, 185481.76079999998910353 151894.13879999998607673, 185444.85599999999976717 151900.14679999998770654, 185408.25620000000344589 151907.75779999999213032, 185376.08439999999245629 151923.62320000000181608, 185367.87599999998928979 151937.72599999999511056, 185361.10019999998621643 151952.26939999999012798, 185357.57440000001224689 151980.91539999999804422, 185357.3152000000118278 152007.42759999999543652, 185362.03640000001178123 152040.63159999999334104, 185374.26620000001275912 152077.10039999999571592, 185391.67420000000856817 152120.51019999998970889, 185413.95920000001206063 152167.91920000000391155, 185450.8393999999971129 152235.094600000011269, 185477.17180000001098961 152276.08059999998658895, 185520.38180000000284053 152337.85180000000400469, 185571.87659999998868443 152398.78700000001117587, 185624.22940000001108274 152455.43140000000130385, 185661.13339999999152496 152499.20139999999082647, 185722.92699999999604188 152583.30939999999827705, 185764.12299999999231659 152657.1190000000060536, 185781.28779999999096617 152702.60540000000037253, 185794.1606000000028871 152733.50219999998807907, 185807.03419999999459833 152748.95100000000093132, 185825.05819999999948777 152765.25740000000223517, 185843.93979999999282882 152770.40700000000651926, 185860.24540000001434237 152773.83979999998700805, 185888.56859999999869615 152768.6902000000118278, 185926.3301999999966938 152747.23420000000623986, 185984.69180000000051223 152700.03099999998812564, 186061.93340000000898726 152630.51339999999618158, 186165.78140000000712462 152564.42860000001383014, 186240.44860000000335276 152529.24059999999008141, 186303.09979999999632128 152513.79180000000633299, 186339.14459999999962747 152511.2173999999940861, 186369.18619999999646097 152519.79980000000796281, 186384.63260000001173466 152528.38219999999273568, 186394.93340000000898726 152544.68859999999403954, 186402.65499999999883585 152569.57740000000922009, 186407.80700000000069849 152588.45900000000256114, 186410.37979999999515712 152609.91500000000814907, 186410.37979999999515712 152646.81979999999748543, 186409.37160000001313165 152678.10300000000279397, 186399.07320000001345761 152742.90040000001317821, 186377.61720000000786968 152824.00440000000526197, 186350.58199999999487773 152896.9551999999966938, 186283.63880000001518056 153087.91479999999864958, 186239.01039999999920838 153235.10339999999268912, 186208.54279999999562278 153320.49880000000121072, 186161.33960000000661239 153406.75239999999757856, 186143.31659999999101274 153435.93280000000959262, 186120.14379999999073334 153463.82560000001103617, 186060.06659999999101274 153521.75719999999273568, 185967.37580000000889413 153595.99520000000484288, 185865.24499999999534339 153672.80819999999948777, 185791.00700000001234002 153721.72820000001229346, 185766.97620000000461005 153741.89660000000731088, 185756.24820000000181608 153753.48300000000745058, 185749.38219999999273568 153768.93140000000130385, 185745.09100000001490116 153786.95459999999729916, 185742.94539999999688007 153817.42220000000088476, 185746.37820000000647269 153832.87059999999473803, 185754.53179999999701977 153845.3152000000118278, 185809.03020000000833534 153895.52259999999660067, 185875.5438000000140164 153944.87140000000363216, 185900.86220000000321306 153959.46179999999003485, 185932.18780000001424924 153970.18979999999282882, 185954.931799999991199 153972.76459999999497086, 185981.96619999999529682 153971.90619999999762513, 186015.43739999999525025 153964.61100000000442378, 186050.41120000000228174 153954.6339999999909196, 186090.10540000000037253 153941.43859999999403954, 186109.844600000011269 153932.85620000000926666, 186122.71820000000298023 153922.98620000001392327, 186136.87979999999515712 153905.82139999998616986, 186144.35279999999329448 153892.94760000001406297, 186152.32800000000861473 153873.42259999999077991, 186161.76840000000083819 153835.23079999999026768, 186172.33799999998882413 153805.24640000000363216, 186189.66140000001178123 153768.07320000001345761, 186212.83420000001206063 153732.02679999999236315, 186242.01420000000507571 153690.40200000000186265, 186277.6309999999939464 153653.92660000000614673, 186308.09899999998742715 153632.89960000000428408, 186336.42060000001220033 153617.45120000001043081, 186360.02220000000670552 153609.29800000000977889, 186396.06859999999869615 153603.29019999998854473, 186426.96619999999529682 153603.29019999998854473, 186468.16140000001178123 153604.1484000000054948, 186493.67139999999199063 153609.84700000000884756, 186510.52859999999054708 153616.34739999999874271, 186544.24299999998765998 153636.62020000000484288, 186637.45060000001103617 153703.49059999999008141, 186703.10620000000926666 153768.28779999999096617, 186776.27160000000731088 153863.33819999999832362, 186860.80819999999948777 153989.92900000000372529, 186895.56739999999990687 154058.58879999999771826, 186916.59380000000237487 154131.53959999998915009, 186930.75539999999455176 154189.47099999999045394, 186944.05780000000959262 154253.83919999998761341, 186963.36819999999715947 154359.83240000001387671, 186972.8097999999881722 154447.80280000000493601, 186984.8242000000027474 154561.09100000001490116, 186992.38880000001518056 154654.0530000000144355, 186989.41399999998975545 154671.5712000000057742, 186985.44760000001406297 154680.82600000000093132, 186978.50640000001294538 154689.19959999999264255, 186970.35320000001229346 154696.47119999999995343, 186952.77999999999883585 154698.72980000000097789, 186935.20660000000498258 154696.25080000000889413, 186905.67900000000372529 154685.67379999998956919, 186828.33439999999245629 154636.64480000000912696, 186791.75539999999455176 154616.92319999999017455, 186758.7021999999997206 154605.905399999988731, 186734.21700000000419095 154607.86520000000018626, 186703.32019999998738058 154613.01459999999497086, 186672.42420000000856817 154619.45139999999082647, 186643.67259999999077991 154633.61259999999310821, 186625.22060000000055879 154648.20259999998961575, 186609.34299999999348074 154684.67819999999483116, 186604.61859999998705462 154706.55239999998593703, 186602.47700000001350418 154726.73219999999855645, 186600.76060000000870787 154766.64060000001336448, 186603.73699999999371357 154816.95000000001164153, 186611.05939999999827705 154858.9016000000119675, 186636.37779999998747371 154976.05220000000554137, 186657.99900000001071021 155044.7417999999888707, 186682.01780000000144355 155102.91539999999804422, 186717.9106000000028871 155170.0151999999943655, 186758.04060000000754371 155253.77700000000186265, 186767.04500000001280569 155283.09919999999692664, 186770.04660000000149012 155314.73040000000037253, 186762.39199999999254942 155343.15700000000651926, 186747.8483999999880325 155367.3961999999883119, 186721.02019999999902211 155400.17379999998956919, 186693.69599999999627471 155423.75179999999818392, 186653.54259999998612329 155449.37359999999171123, 186623.93299999998998828 155460.95999999999185093, 186602.47700000001350418 155464.3931999999913387, 186582.63680000000749715 155462.97479999999632128, 186561.48279999999795109 155456.36420000001089647, 186548.04120000000693835 155448.65179999999236315, 186536.58259999999427237 155439.17660000000614673, 186526.73699999999371357 155428.77580000000307336, 186510.53219999998691492 155404.08280000000377186, 186496.44860000000335276 155363.6780000000144355, 186491.13819999998668209 155327.66000000000349246, 186491.13800000000628643 155296.72159999998984858, 186496.50640000001294538 155259.49139999999897555, 186511.91759999998612329 155209.90900000001420267, 186526.66719999999622814 155174.08979999998700805, 186532.26459999999497086 155147.07939999998779967, 186531.5719999999855645 155122.02859999999054708, 186528.33960000000661239 155107.02100000000791624, 186522.10560000000987202 155094.55340000000433065, 186511.94659999999566935 155084.62520000000949949, 186499.13260000001173466 155076.54440000001341105, 186480.77720000001136214 155077.81419999999343418, 186467.15499999999883585 155080.93119999999180436, 186438.06380000000353903 155091.78279999998630956, 186414.16719999999622814 155102.51879999999073334, 186387.03820000000996515 155118.79620000001159497, 186348.8660000000090804 155144.6969999999855645, 186301.01879999999073334 155187.50179999999818392, 186258.10599999999976717 155228.69779999999445863, 186196.31320000000414439 155282.76699999999254942, 186155.54579999999259599 155314.09299999999348074, 186098.04339999999501742 155348.4228000000002794, 186050.41159999999217689 155368.59140000000479631, 186002.66200000001117587 155383.4266000000061 | B2: r-nul Leova, or. Leova (Merged) | C2: or. Leova | D2: 9999 | E2: =IF(LEN(D2)=3,"0"&TEXT(D2,0),TEXT(D2,0)) -> 9999 | F2: 103.464
